<?xml version="1.0" ?>
<!-- =================================================================================== -->
<!-- |    This document was autogenerated by xacro from human_model.xacro              | -->
<!-- |    EDITING THIS FILE BY HAND IS NOT RECOMMENDED                                 | -->
<!-- =================================================================================== -->
<robot name="hooman" xmlns:xacro="http://www.ros.org/wiki/xacro">
  <!-- From now on, nothing should be changed in the file -->
  --&gt;

  <!-- Define mass normalization value and segment masses -->
  <!-- Materials -->
  <material name="blue">
    <color rgba="0 0 0.6 1"/>
  </material>
  <link name="root">
    <inertial>
      <mass value="0.001"/>
      <origin rpy="0 0 0" xyz="0 0 0"/>
      <inertia ixx="4e-08" ixy="0" ixz="0" iyy="4e-08" iyz="0" izz="4e-08"/>
    </inertial>
  </link>
  <link name="pelvis">
    <visual>
      <geometry>
        <box size="0.221801614764 0.174155132641 0.345859400231"/>
      </geometry>
      <origin rpy="0 0 0" xyz="0 0.00642243367935 0"/>
      <material name="blue"/>
    </visual>
    <collision>
      <geometry>
        <box size="0.221801614764 0.174155132641 0.259394550173"/>
      </geometry>
      <origin rpy="0 0 0" xyz="0 0.00642243367935 0"/>
    </collision>
    <inertial>
      <mass value="7.15341845835"/>
      <origin rpy="0 0 0" xyz="0 0.00642243367935 0"/>
      <inertia ixx="0.0893871707018" ixy="0" ixz="0" iyy="0.100633504616" iyz="0" izz="0.047406876412"/>
    </inertial>
  </link>
  <link name="body_L5_1">
    <inertial>
      <mass value="0.001"/>
      <origin rpy="0 0 0" xyz="0 0 0"/>
      <inertia ixx="4e-08" ixy="0" ixz="0" iyy="4e-08" iyz="0" izz="4e-08"/>
    </inertial>
  </link>
  <link name="body_L5_2">
    <inertial>
      <mass value="0.001"/>
      <origin rpy="0 0 0" xyz="0 0 0"/>
      <inertia ixx="4e-08" ixy="0" ixz="0" iyy="4e-08" iyz="0" izz="4e-08"/>
    </inertial>
  </link>
  <link name="lumbar_spine">
    <visual>
      <geometry>
        <box size="0.211719723183  0.1785 0.284359861592"/>
      </geometry>
      <origin rpy="0 0 0" xyz="0 0.08925 0"/>
      <material name="blue"/>
    </visual>
    <collision>
      <geometry>
        <box size="0.211719723183  0.1785 0.213269896194"/>
      </geometry>
      <origin rpy="0 0 0" xyz="0 0.08925 0"/>
    </collision>
    <inertial>
      <mass value="10.4080382663"/>
      <origin rpy="0 0 0" xyz="0 0.08925 0"/>
      <inertia ixx="0.0977685847445" ixy="0" ixz="0" iyy="0.109011860436" iyz="0" izz="0.0665138619002"/>
    </inertial>
  </link>
  <link name="body_T12_1">
    <inertial>
      <mass value="0.001"/>
      <origin rpy="0 0 0" xyz="0 0 0"/>
      <inertia ixx="4e-08" ixy="0" ixz="0" iyy="4e-08" iyz="0" izz="4e-08"/>
    </inertial>
  </link>
  <link name="body_T12_2">
    <inertial>
      <mass value="0.001"/>
      <origin rpy="0 0 0" xyz="0 0 0"/>
      <inertia ixx="4e-08" ixy="0" ixz="0" iyy="4e-08" iyz="0" izz="4e-08"/>
    </inertial>
  </link>
  <link name="thoracic_spine">
    <visual>
      <geometry>
        <box size="0.201637831603 0.221 0.350718915802"/>
      </geometry>
      <origin rpy="0 0 0" xyz="0 0.1105 0"/>
      <material name="blue"/>
    </visual>
    <collision>
      <geometry>
        <box size="0.201637831603 0.221 0.350718915802"/>
      </geometry>
      <origin rpy="0 0 0" xyz="0 0.1105 0"/>
    </collision>
    <inertial>
      <mass value="9.32987685629"/>
      <origin rpy="0 0 0" xyz="0 0.1105 0"/>
      <inertia ixx="0.133607535801" ixy="0" ixz="0" iyy="0.127245193543" iyz="0" izz="0.0695844103317"/>
    </inertial>
  </link>
  <link name="body_C7_1">
    <inertial>
      <mass value="0.001"/>
      <origin rpy="0 0 0" xyz="0 0 0"/>
      <inertia ixx="4e-08" ixy="0" ixz="0" iyy="4e-08" iyz="0" izz="4e-08"/>
    </inertial>
  </link>
  <link name="body_C7_2">
    <inertial>
      <mass value="0.001"/>
      <origin rpy="0 0 0" xyz="0 0 0"/>
      <inertia ixx="4e-08" ixy="0" ixz="0" iyy="4e-08" iyz="0" izz="4e-08"/>
    </inertial>
  </link>
  <link name="neck">
    <visual>
      <geometry>
        <cylinder length="0.0935" radius="0.0453685121107"/>
      </geometry>
      <origin rpy="-1.57079632679 0 0" xyz="0 0.04675 0"/>
      <material name="blue"/>
    </visual>
    <collision>
      <geometry>
        <cylinder length="0.0935" radius="0.0453685121107"/>
      </geometry>
      <origin rpy="-1.57079632679 0 0" xyz="0 0.04675 0"/>
    </collision>
    <inertial>
      <mass value="0.482784902231"/>
      <origin rpy="-1.57079632679 0 0" xyz="0 0.04675 0"/>
      <inertia ixx="0.000600148128613" ixy="0" ixz="0" iyy="0.000600148128613" iyz="0" izz="0.000496858538638"/>
    </inertial>
  </link>
  <link name="body_C1">
    <inertial>
      <mass value="0.001"/>
      <origin rpy="0 0 0" xyz="0 0 0"/>
      <inertia ixx="4e-08" ixy="0" ixz="0" iyy="4e-08" iyz="0" izz="4e-08"/>
    </inertial>
  </link>
  <link name="head">
    <visual>
      <geometry>
        <cylinder length="0.23375" radius="0.1"/>
      </geometry>
      <origin rpy="-1.57079632679 0 0" xyz="0 0.095625 0"/>
      <material name="blue"/>
    </visual>
    <collision>
      <geometry>
        <cylinder length="0.23375" radius="0.1"/>
      </geometry>
      <origin rpy="-1.57079632679 0 0" xyz="0 0.095625 0"/>
    </collision>
    <inertial>
      <mass value="4.34506412008"/>
      <origin rpy="-1.57079632679 0 0" xyz="0 0.095625 0"/>
      <inertia ixx="0.0306468461355" ixy="0" ixz="0" iyy="0.0306468461355" iyz="0" izz="0.0217253206004"/>
    </inertial>
  </link>
  <link name="body_CSJ_right_clavicular">
    <inertial>
      <mass value="0.001"/>
      <origin rpy="0 0 0" xyz="0 0 0"/>
      <inertia ixx="4e-08" ixy="0" ixz="0" iyy="4e-08" iyz="0" izz="4e-08"/>
    </inertial>
  </link>
  <link name="right_clavicular">
    <visual>
      <geometry>
        <cylinder length="0.151725" radius="0.060491349481"/>
      </geometry>
      <origin rpy="0 0 0" xyz="0 0 0.0758625"/>
      <material name="blue"/>
    </visual>
    <inertial>
      <mass value="0.518326492016"/>
      <origin rpy="0 0 0" xyz="0 0 0.0758625"/>
      <inertia ixx="0.00146850904182" ixy="0" ixz="0" iyy="0.00146850904182" iyz="0" izz="0.000948331021107"/>
    </inertial>
  </link>
  <link name="body_right_shoulder_1">
    <inertial>
      <mass value="0.001"/>
      <origin rpy="0 0 0" xyz="0 0 0"/>
      <inertia ixx="4e-08" ixy="0" ixz="0" iyy="4e-08" iyz="0" izz="4e-08"/>
    </inertial>
  </link>
  <link name="body_right_shoulder_2">
    <inertial>
      <mass value="0.001"/>
      <origin rpy="0 0 0" xyz="0 0 0"/>
      <inertia ixx="4e-08" ixy="0" ixz="0" iyy="4e-08" iyz="0" izz="4e-08"/>
    </inertial>
  </link>
  <link name="right_arm">
    <visual>
      <geometry>
        <cylinder length="0.323" radius="0.0504094579008"/>
      </geometry>
      <origin rpy="1.57079632679 0 0" xyz="0 -0.1615 0"/>
      <material name="blue"/>
    </visual>
    <collision>
      <geometry>
        <cylinder length="0.323" radius="0.0504094579008"/>
      </geometry>
      <origin rpy="1.57079632679 0 0" xyz="0 -0.1615 0"/>
    </collision>
    <inertial>
      <mass value="1.74495037103"/>
      <origin rpy="1.57079632679 0 0" xyz="0 -0.1615 0"/>
      <inertia ixx="0.0162792731508" ixy="0" ixz="0" iyy="0.0162792731508" iyz="0" izz="0.00221705842508"/>
    </inertial>
  </link>
  <link name="body_right_elbow">
    <inertial>
      <mass value="0.001"/>
      <origin rpy="0 0 0" xyz="0 0 0"/>
      <inertia ixx="4e-08" ixy="0" ixz="0" iyy="4e-08" iyz="0" izz="4e-08"/>
    </inertial>
  </link>
  <link name="right_forearm">
    <visual>
      <geometry>
        <cylinder length="0.255" radius="0.0403275663206"/>
      </geometry>
      <origin rpy="1.57079632679 0 0" xyz="0 -0.1275 0"/>
      <material name="blue"/>
    </visual>
    <collision>
      <geometry>
        <cylinder length="0.255" radius="0.0403275663206"/>
      </geometry>
      <origin rpy="1.57079632679 0 0" xyz="0 -0.1275 0"/>
    </collision>
    <inertial>
      <mass value="1.06160792958"/>
      <origin rpy="1.57079632679 0 0" xyz="0 -0.1275 0"/>
      <inertia ixx="0.00618421455788" ixy="0" ixz="0" iyy="0.00618421455788" iyz="0" izz="0.000863253178908"/>
    </inertial>
  </link>
  <link name="body_right_wrist">
    <inertial>
      <mass value="0.001"/>
      <origin rpy="0 0 0" xyz="0 0 0"/>
      <inertia ixx="4e-08" ixy="0" ixz="0" iyy="4e-08" iyz="0" izz="4e-08"/>
    </inertial>
  </link>
  <link name="right_hand">
    <visual>
      <geometry>
        <box size="0.0302456747405 0.17 0.0806551326413"/>
      </geometry>
      <origin rpy="0 0 0" xyz="0 -0.085 0"/>
      <material name="blue"/>
    </visual>
    <collision>
      <geometry>
        <box size="0.0302456747405 0.17 0.0806551326413"/>
      </geometry>
      <origin rpy="0 0 0" xyz="0 -0.085 0"/>
    </collision>
    <inertial>
      <mass value="0.41408646156"/>
      <origin rpy="0 0 0" xyz="0 -0.085 0"/>
      <inertia ixx="0.00122173623897" ixy="0" ixz="0" iyy="0.000256045230969" iyz="0" izz="0.00102882544851"/>
    </inertial>
  </link>
  <link name="body_CSJ_left_clavicular">
    <inertial>
      <mass value="0.001"/>
      <origin rpy="0 0 0" xyz="0 0 0"/>
      <inertia ixx="4e-08" ixy="0" ixz="0" iyy="4e-08" iyz="0" izz="4e-08"/>
    </inertial>
  </link>
  <link name="left_clavicular">
    <visual>
      <geometry>
        <cylinder length="0.151725" radius="0.060491349481"/>
      </geometry>
      <origin rpy="0 0 0" xyz="0 0 -0.0758625"/>
      <material name="blue"/>
    </visual>
    <inertial>
      <mass value="0.518326492016"/>
      <origin rpy="0 0 0" xyz="0 0 -0.0758625"/>
      <inertia ixx="0.00146850904182" ixy="0" ixz="0" iyy="0.00146850904182" iyz="0" izz="0.000948331021107"/>
    </inertial>
  </link>
  <link name="body_left_shoulder_1">
    <inertial>
      <mass value="0.001"/>
      <origin rpy="0 0 0" xyz="0 0 0"/>
      <inertia ixx="4e-08" ixy="0" ixz="0" iyy="4e-08" iyz="0" izz="4e-08"/>
    </inertial>
  </link>
  <link name="body_left_shoulder_2">
    <inertial>
      <mass value="0.001"/>
      <origin rpy="0 0 0" xyz="0 0 0"/>
      <inertia ixx="4e-08" ixy="0" ixz="0" iyy="4e-08" iyz="0" izz="4e-08"/>
    </inertial>
  </link>
  <link name="left_arm">
    <visual>
      <geometry>
        <cylinder length="0.323" radius="0.0504094579008"/>
      </geometry>
      <origin rpy="1.57079632679 0 0" xyz="0 -0.1615 0"/>
      <material name="blue"/>
    </visual>
    <collision>
      <geometry>
        <cylinder length="0.323" radius="0.0504094579008"/>
      </geometry>
      <origin rpy="1.57079632679 0 0" xyz="0 -0.1615 0"/>
    </collision>
    <inertial>
      <mass value="1.74495037103"/>
      <origin rpy="1.57079632679 0 0" xyz="0 -0.1615 0"/>
      &gt;
			
      <inertia ixx="0.0162792731508" ixy="0" ixz="0" iyy="0.0162792731508" iyz="0" izz="0.00221705842508"/>
    </inertial>
  </link>
  <link name="body_left_elbow">
    <inertial>
      <mass value="0.001"/>
      <origin rpy="0 0 0" xyz="0 0 0"/>
      <inertia ixx="4e-08" ixy="0" ixz="0" iyy="4e-08" iyz="0" izz="4e-08"/>
    </inertial>
  </link>
  <link name="left_forearm">
    <visual>
      <geometry>
        <cylinder length="0.255" radius="0.0403275663206"/>
      </geometry>
      <origin rpy="1.57079632679 0 0" xyz="0 -0.1275 0"/>
      <material name="blue"/>
    </visual>
    <collision>
      <geometry>
        <cylinder length="0.255" radius="0.0403275663206"/>
      </geometry>
      <origin rpy="1.57079632679 0 0" xyz="0 -0.1275 0"/>
    </collision>
    <inertial>
      <mass value="1.06160792958"/>
      <origin rpy="1.57079632679 0 0" xyz="0 -0.1275 0"/>
      <inertia ixx="0.00618421455788" ixy="0" ixz="0" iyy="0.00618421455788" iyz="0" izz="0.000863253178908"/>
    </inertial>
  </link>
  <link name="body_left_wrist">
    <inertial>
      <mass value="0.001"/>
      <origin rpy="0 0 0" xyz="0 0 0"/>
      <inertia ixx="4e-08" ixy="0" ixz="0" iyy="4e-08" iyz="0" izz="4e-08"/>
    </inertial>
  </link>
  <link name="left_hand">
    <visual>
      <geometry>
        <box size="0.0302456747405 0.17 0.0806551326413"/>
      </geometry>
      <origin rpy="0 0 0" xyz="0 -0.085 0"/>
      <material name="blue"/>
    </visual>
    <collision>
      <geometry>
        <box size="0.0302456747405 0.17 0.0806551326413"/>
      </geometry>
      <origin rpy="0 0 0" xyz="0 -0.085 0"/>
    </collision>
    <inertial>
      <mass value="0.41408646156"/>
      <origin rpy="0 0 0" xyz="0 -0.085 0"/>
      <inertia ixx="0.00122173623897" ixy="0" ixz="0" iyy="0.000256045230969" iyz="0" izz="0.00102882544851"/>
    </inertial>
  </link>
  <link name="body_right_hip_1">
    <inertial>
      <mass value="0.001"/>
      <origin rpy="0 0 0" xyz="0 0 0"/>
      <inertia ixx="4e-08" ixy="0" ixz="0" iyy="4e-08" iyz="0" izz="4e-08"/>
    </inertial>
  </link>
  <link name="body_right_hip_2">
    <inertial>
      <mass value="0.001"/>
      <origin rpy="0 0 0" xyz="0 0 0"/>
      <inertia ixx="4e-08" ixy="0" ixz="0" iyy="4e-08" iyz="0" izz="4e-08"/>
    </inertial>
  </link>
  <link name="right_thigh">
    <visual>
      <geometry>
        <cylinder length="0.442" radius="0.0806551326413"/>
      </geometry>
      <origin rpy="1.57079632679 0 0" xyz="0 -0.221 0"/>
      <material name="blue"/>
    </visual>
    <collision>
      <geometry>
        <cylinder length="0.442" radius="0.0806551326413"/>
      </geometry>
      <origin rpy="1.57079632679 0 0" xyz="0 -0.221 0"/>
    </collision>
    <inertial>
      <mass value="9.16927117713"/>
      <origin rpy="1.57079632679 0 0" xyz="0 -0.221 0"/>
      <inertia ixx="0.164190892485" ixy="0" ixz="0" iyy="0.164190892485" iyz="0" izz="0.0298242025944"/>
    </inertial>
  </link>
  <link name="body_right_knee">
    <inertial>
      <mass value="0.001"/>
      <origin rpy="0 0 0" xyz="0 0 0"/>
      <inertia ixx="4e-08" ixy="0" ixz="0" iyy="4e-08" iyz="0" izz="4e-08"/>
    </inertial>
  </link>
  <link name="right_shank">
    <visual>
      <geometry>
        <cylinder length="0.391" radius="0.060491349481"/>
      </geometry>
      <origin rpy="1.57079632679 0 0" xyz="0 -0.1955 0"/>
      <material name="blue"/>
    </visual>
    <collision>
      <geometry>
        <cylinder length="0.391" radius="0.060491349481"/>
      </geometry>
      <origin rpy="1.57079632679 0 0" xyz="0 -0.1955 0"/>
    </collision>
    <inertial>
      <mass value="2.80920246717"/>
      <origin rpy="1.57079632679 0 0" xyz="0 -0.1955 0"/>
      <inertia ixx="0.0383593343101" ixy="0" ixz="0" iyy="0.0383593343101" iyz="0" izz="0.00513972155625"/>
    </inertial>
  </link>
  <link name="body_right_ankle">
    <inertial>
      <mass value="0.001"/>
      <origin rpy="0 0 0" xyz="0 0 0"/>
      <inertia ixx="4e-08" ixy="0" ixz="0" iyy="4e-08" iyz="0" izz="4e-08"/>
    </inertial>
  </link>
  <link name="right_foot">
    <visual>
      <geometry>
        <box size="0.2584 0.068 0.10336"/>
      </geometry>
      <origin rpy="0 0 0" xyz="0.07752 -0.034 0"/>
      <material name="blue"/>
    </visual>
    <collision>
      <geometry>
        <box size="0.2584 0.068 0.10336"/>
      </geometry>
      <origin rpy="0 0 0" xyz="0.07752 -0.034 0"/>
    </collision>
    <inertial>
      <mass value="0.910491316081"/>
      <origin rpy="0 0 0" xyz="0.07752 -0.034 0"/>
      <inertia ixx="0.00116142952113" ixy="0" ixz="0" iyy="0.00587675478815" iyz="0" izz="0.00541701057462"/>
    </inertial>
  </link>
  <link name="body_left_hip_1">
    <inertial>
      <mass value="0.001"/>
      <origin rpy="0 0 0" xyz="0 0 0"/>
      <inertia ixx="4e-08" ixy="0" ixz="0" iyy="4e-08" iyz="0" izz="4e-08"/>
    </inertial>
  </link>
  <link name="body_left_hip_2">
    <inertial>
      <mass value="0.001"/>
      <origin rpy="0 0 0" xyz="0 0 0"/>
      <inertia ixx="4e-08" ixy="0" ixz="0" iyy="4e-08" iyz="0" izz="4e-08"/>
    </inertial>
  </link>
  <link name="left_thigh">
    <visual>
      <geometry>
        <cylinder length="0.442" radius="0.0806551326413"/>
      </geometry>
      <origin rpy="1.57079632679 0 0" xyz="0 -0.221 0"/>
      <material name="blue"/>
    </visual>
    <collision>
      <geometry>
        <cylinder length="0.442" radius="0.0806551326413"/>
      </geometry>
      <origin rpy="1.57079632679 0 0" xyz="0 -0.221 0"/>
    </collision>
    <inertial>
      <mass value="9.16927117713"/>
      <origin rpy="1.57079632679 0 0" xyz="0 -0.221 0"/>
      <inertia ixx="0.164190892485" ixy="0" ixz="0" iyy="0.164190892485" iyz="0" izz="0.0298242025944"/>
    </inertial>
  </link>
  <link name="body_left_knee">
    <inertial>
      <mass value="0.001"/>
      <origin rpy="0 0 0" xyz="0 0 0"/>
      <inertia ixx="4e-08" ixy="0" ixz="0" iyy="4e-08" iyz="0" izz="4e-08"/>
    </inertial>
  </link>
  <link name="left_shank">
    <visual>
      <geometry>
        <cylinder length="0.391" radius="0.060491349481"/>
      </geometry>
      <origin rpy="1.57079632679 0 0" xyz="0 -0.1955 0"/>
      <material name="blue"/>
    </visual>
    <collision>
      <geometry>
        <cylinder length="-0.391" radius="0.060491349481"/>
      </geometry>
      <origin rpy="1.57079632679 0 0" xyz="0 -0.1955 0"/>
    </collision>
    <inertial>
      <mass value="2.80920246717"/>
      <origin rpy="1.57079632679 0 0" xyz="0 -0.1955 0"/>
      <inertia ixx="0.0383593343101" ixy="0" ixz="0" iyy="0.0383593343101" iyz="0" izz="0.00513972155625"/>
    </inertial>
  </link>
  <link name="body_left_ankle">
    <inertial>
      <mass value="0.001"/>
      <origin rpy="0 0 0" xyz="0 0 0"/>
      <inertia ixx="4e-08" ixy="0" ixz="0" iyy="4e-08" iyz="0" izz="4e-08"/>
    </inertial>
  </link>
  <link name="left_foot">
    <visual>
      <geometry>
        <box size="0.2584 0.068 0.10336"/>
      </geometry>
      <origin rpy="0 0 0" xyz="0.07752 -0.034 0"/>
      <material name="blue"/>
    </visual>
    <collision>
      <geometry>
        <box size="0.2584 0.068 0.10336"/>
      </geometry>
      <origin rpy="0 0 0" xyz="0.07752 -0.034 0"/>
    </collision>
    <inertial>
      <mass value="0.910491316081"/>
      <origin rpy="0 0 0" xyz="0.07752 -0.034 0"/>
      <inertia ixx="0.00116142952113" ixy="0" ixz="0" iyy="0.00587675478815" iyz="0" izz="0.00541701057462"/>
    </inertial>
  </link>
  <!-- Define joints -->
  <!-- Joint for correct pelvis orientation -->
  <joint name="root_ISB_orientation" type="fixed">
    <parent link="root"/>
    <child link="pelvis"/>
    <origin rpy="1.57079632679 0 0" xyz="0 0 0"/>
  </joint>
  <!-- Back joints -->
  <joint name="lumbarspine_abduction" type="revolute">
    <parent link="pelvis"/>
    <child link="body_L5_1"/>
    <axis xyz="1 0 0"/>
    <origin xyz="0 0.0935 0"/>
    <limit effort="155.0" lower="-0.261799387799" upper="0.261799387799" velocity="1.0"/>
    <dynamics damping="0.01" friction="0.0"/>
  </joint>
  <joint name="lumbarspine_rotation" type="revolute">
    <parent link="body_L5_1"/>
    <child link="body_L5_2"/>
    <axis xyz="0 1 0"/>
    <origin xyz="0 0 0"/>
    <limit effort="65.0" lower="-0.349065850399" upper="0.349065850399" velocity="1.0"/>
    <dynamics damping="0.01" friction="0.0"/>
  </joint>
  <joint name="lumbarspine_flexion" type="revolute">
    <parent link="body_L5_2"/>
    <child link="lumbar_spine"/>
    <axis xyz="0 0 1"/>
    <origin xyz="0 0 0"/>
    <limit effort="228.0" lower="-0.436332312999" upper="0.174532925199" velocity="1.0"/>
    <dynamics damping="0.01" friction="0.0"/>
  </joint>
  <joint name="thoracicspine_abduction" type="revolute">
    <parent link="lumbar_spine"/>
    <child link="body_T12_1"/>
    <axis xyz="1 0 0"/>
    <origin xyz="0 0.1785 0"/>
    <limit effort="155.0" lower="-0.261799387799" upper="0.261799387799" velocity="1.0"/>
    <dynamics damping="0.01" friction="0.0"/>
  </joint>
  <joint name="thoracicspine_rotation" type="revolute">
    <parent link="body_T12_1"/>
    <child link="body_T12_2"/>
    <axis xyz="0 1 0"/>
    <origin xyz="0 0 0"/>
    <limit effort="65.0" lower="-0.261799387799" upper="0.261799387799" velocity="1.0"/>
    <dynamics damping="0.01" friction="0.0"/>
  </joint>
  <joint name="thoracicspine_flexion" type="revolute">
    <parent link="body_T12_2"/>
    <child link="thoracic_spine"/>
    <axis xyz="0 0 1"/>
    <origin xyz="0 0 0"/>
    <limit effort="228.0" lower="-0.436332312999" upper="0.174532925199" velocity="1.0"/>
    <dynamics damping="0.01" friction="0.0"/>
  </joint>
  <joint name="neck_abduction" type="revolute">
    <parent link="thoracic_spine"/>
    <child link="body_C7_1"/>
    <axis xyz="1 0 0"/>
    <origin xyz="0 0.221 0"/>
    <limit effort="50" lower="-0.436332312999" upper="0.436332312999" velocity="1.0"/>
    <dynamics damping="0.01" friction="0.0"/>
  </joint>
  <joint name="neck_rotation" type="revolute">
    <parent link="body_C7_1"/>
    <child link="body_C7_2"/>
    <axis xyz="0 1 0"/>
    <origin xyz="0 0 0"/>
    <limit effort="50" lower="-1.4835298642" upper="1.4835298642" velocity="1.0"/>
    <dynamics damping="0.01" friction="0.0"/>
  </joint>
  <joint name="neck_flexion" type="revolute">
    <parent link="body_C7_2"/>
    <child link="neck"/>
    <axis xyz="0 0 1"/>
    <origin xyz="0 0 0"/>
    <limit effort="50" lower="-0.785398163397" upper="0.436332312999" velocity="1.0"/>
    <dynamics damping="0.01" friction="0.0"/>
  </joint>
  <joint name="head_abduction" type="revolute">
    <parent link="neck"/>
    <child link="body_C1"/>
    <axis xyz="1 0 0"/>
    <origin xyz="0 0.0935 0"/>
    <limit effort="20" lower="-0.436332312999" upper="0.436332312999" velocity="1.0"/>
    <dynamics damping="0.01" friction="0.0"/>
  </joint>
  <joint name="head_flexion" type="revolute">
    <parent link="body_C1"/>
    <child link="head"/>
    <axis xyz="0 0 1"/>
    <origin xyz="0 0 0"/>
    <limit effort="20" lower="-0.698131700798" upper="0.436332312999" velocity="1.0"/>
    <dynamics damping="0.01" friction="0.0"/>
  </joint>
  <!-- Right arm joints -->
  <joint name="right_clavicular_flexion" type="revolute">
    <parent link="thoracic_spine"/>
    <child link="body_CSJ_right_clavicular"/>
    <axis xyz="1 0 0"/>
    <origin xyz="0 0.1785 0.026775"/>
    <limit effort="105.0" lower="-0.698131700798" upper="0.174532925199" velocity="1.0"/>
    <dynamics damping="0.01" friction="0.0"/>
  </joint>
  <joint name="right_clavicular_abduction" type="revolute">
    <parent link="body_CSJ_right_clavicular"/>
    <child link="right_clavicular"/>
    <axis xyz="0 1 0"/>
    <origin xyz="0 0 0"/>
    <limit effort="107.0" lower="-0.261799387799" upper="0.349065850399" velocity="1.0"/>
    <dynamics damping="0.01" friction="0.0"/>
  </joint>
  <joint name="right_shoulder_abduction" type="revolute">
    <parent link="right_clavicular"/>
    <child link="body_right_shoulder_1"/>
    <axis xyz="1 0 0"/>
    <origin xyz="0 0 0.151725"/>
    <limit effort="69.0" lower="-2.33874119767" upper="0.837758040957" velocity="1.0"/>
    <dynamics damping="0.01" friction="0.0"/>
  </joint>
  <joint name="right_shoulder_rotation" type="revolute">
    <parent link="body_right_shoulder_1"/>
    <child link="body_right_shoulder_2"/>
    <axis xyz="0 1 0"/>
    <origin xyz="0 0 0"/>
    <limit effort="51.0" lower="-0.593411945678" upper="1.69296937443" velocity="1.0"/>
    <dynamics damping="0.01" friction="0.0"/>
  </joint>
  <joint name="right_shoulder_flexion" type="revolute">
    <parent link="body_right_shoulder_2"/>
    <child link="right_arm"/>
    <axis xyz="0 0 1"/>
    <origin xyz="0 0 0"/>
    <limit effort="90.0" lower="-1.06465084372" upper="3.28121899375" velocity="1.0"/>
    <dynamics damping="0.01" friction="0.0"/>
  </joint>
  <joint name="right_elbow_flexion" type="revolute">
    <parent link="right_arm"/>
    <child link="body_right_elbow"/>
    <axis xyz="0 0 1"/>
    <origin xyz="0 -0.323 0"/>
    <limit effort="75.0" lower="0.0" upper="2.47836753783" velocity="1.0"/>
    <dynamics damping="0.01" friction="0.0"/>
  </joint>
  <joint name="right_elbow_rotation" type="revolute">
    <parent link="body_right_elbow"/>
    <child link="right_forearm"/>
    <axis xyz="0 1 0"/>
    <origin xyz="0 0 0"/>
    <limit effort="13.0" lower="-0.401425727959" upper="2.91469985083" velocity="1.0"/>
    <dynamics damping="0.01" friction="0.0"/>
  </joint>
  <joint name="right_wrist_flexion" type="revolute">
    <parent link="right_forearm"/>
    <child link="body_right_wrist"/>
    <axis xyz="0 0 1"/>
    <origin xyz="0 -0.255 0"/>
    <limit effort="10.0" lower="-1.72787595947" upper="1.57079632679" velocity="1.0"/>
    <dynamics damping="0.01" friction="0.0"/>
  </joint>
  <joint name="right_wrist_abduction" type="revolute">
    <parent link="body_right_wrist"/>
    <child link="right_hand"/>
    <axis xyz="1 0 0"/>
    <origin xyz="0 0 0"/>
    <limit effort="11.0" lower="-0.820304748437" upper="0.471238898038" velocity="1.0"/>
    <dynamics damping="0.01" friction="0.0"/>
  </joint>
  <!-- Left arm joints -->
  <joint name="left_clavicular_flexion" type="revolute">
    <parent link="thoracic_spine"/>
    <child link="body_CSJ_left_clavicular"/>
    <axis xyz="1 0 0"/>
    <origin xyz="0 0.1785 -0.026775"/>
    <limit effort="105.0" lower="-0.174532925199" upper="0.698131700798" velocity="1.0"/>
    <dynamics damping="0.01" friction="0.0"/>
  </joint>
  <joint name="left_clavicular_abduction" type="revolute">
    <parent link="body_CSJ_left_clavicular"/>
    <child link="left_clavicular"/>
    <axis xyz="0 1 0"/>
    <origin xyz="0 0 0"/>
    <limit effort="107.0" lower="-0.349065850399" upper="0.261799387799" velocity="1.0"/>
    <dynamics damping="0.01" friction="0.0"/>
  </joint>
  <joint name="left_shoulder_abduction" type="revolute">
    <parent link="left_clavicular"/>
    <child link="body_left_shoulder_1"/>
    <axis xyz="1 0 0"/>
    <origin xyz="0 0 -0.151725"/>
    <limit effort="69.0" lower="-0.837758040957" upper="2.33874119767" velocity="1.0"/>
    <dynamics damping="0.01" friction="0.0"/>
  </joint>
  <joint name="left_shoulder_rotation" type="revolute">
    <parent link="body_left_shoulder_1"/>
    <child link="body_left_shoulder_2"/>
    <axis xyz="0 1 0"/>
    <origin xyz="0 0 0"/>
    <limit effort="51.0" lower="-1.69296937443" upper="0.593411945678" velocity="1.0"/>
    <dynamics damping="0.01" friction="0.0"/>
  </joint>
  <joint name="left_shoulder_flexion" type="revolute">
    <parent link="body_left_shoulder_2"/>
    <child link="left_arm"/>
    <axis xyz="0 0 1"/>
    <origin xyz="0 0 0"/>
    <limit effort="90.0" lower="-1.06465084372" upper="3.28121899375" velocity="1.0"/>
    <dynamics damping="0.01" friction="0.0"/>
  </joint>
  <joint name="left_elbow_flexion" type="revolute">
    <parent link="left_arm"/>
    <child link="body_left_elbow"/>
    <axis xyz="0 0 1"/>
    <origin xyz="0 -0.323 0"/>
    <limit effort="75.0" lower="0.0" upper="2.47836753783" velocity="1.0"/>
    <dynamics damping="0.01" friction="0.0"/>
  </joint>
  <joint name="left_elbow_rotation" type="revolute">
    <parent link="body_left_elbow"/>
    <child link="left_forearm"/>
    <axis xyz="0 1 0"/>
    <origin xyz="0 0 0"/>
    <limit effort="13.0" lower="-2.91469985083" upper="0.401425727959" velocity="1.0"/>
    <dynamics damping="0.01" friction="0.0"/>
  </joint>
  <joint name="left_wrist_flexion" type="revolute">
    <parent link="left_forearm"/>
    <child link="body_left_wrist"/>
    <axis xyz="0 0 1"/>
    <origin xyz="0 -0.255 0"/>
    <limit effort="10.0" lower="-1.57079632679" upper="1.72787595947" velocity="1.0"/>
    <dynamics damping="0.01" friction="0.0"/>
  </joint>
  <joint name="left_wrist_abduction" type="revolute">
    <parent link="body_left_wrist"/>
    <child link="left_hand"/>
    <axis xyz="1 0 0"/>
    <origin xyz="0 0 0"/>
    <limit effort="11.0" lower="-0.471238898038" upper="0.820304748437" velocity="1.0"/>
    <dynamics damping="0.01" friction="0.0"/>
  </joint>
  <!-- Right leg joints -->
  <joint name="right_hip_abduction" type="revolute">
    <parent link="pelvis"/>
    <child link="body_right_hip_1"/>
    <axis xyz="1 0 0"/>
    <origin xyz="0 0 0.08925"/>
    <limit effort="108.0" lower="-0.925024503557" upper="0.541052068118" velocity="1.0"/>
    <dynamics damping="0.01" friction="0.0"/>
  </joint>
  <joint name="right_hip_rotation" type="revolute">
    <parent link="body_right_hip_1"/>
    <child link="body_right_hip_2"/>
    <axis xyz="0 1 0"/>
    <origin xyz="0 0 0"/>
    <limit effort="67.0" lower="-0.593411945678" upper="0.680678408278" velocity="1.0"/>
    <dynamics damping="0.01" friction="0.0"/>
  </joint>
  <joint name="right_hip_flexion" type="revolute">
    <parent link="body_right_hip_2"/>
    <child link="right_thigh"/>
    <axis xyz="0 0 1"/>
    <origin xyz="0 0 0"/>
    <limit effort="186.0" lower="-0.261799387799" upper="1.97222205475" velocity="1.0"/>
    <dynamics damping="0.01" friction="0.0"/>
  </joint>
  <joint name="right_knee_rotation" type="revolute">
    <parent link="right_thigh"/>
    <child link="body_right_knee"/>
    <axis xyz="0 1 0"/>
    <origin xyz="0 -0.442 0"/>
    <limit effort="22.0" lower="-0.750491578358" upper="0.610865238198" velocity="1.0"/>
    <dynamics damping="0.01" friction="0.0"/>
  </joint>
  <joint name="right_knee_flexion" type="revolute">
    <parent link="body_right_knee"/>
    <child link="right_shank"/>
    <axis xyz="0 0 1"/>
    <origin xyz="0 0 0"/>
    <limit effort="164.0" lower="-2.44346095279" upper="0.0872664625997" velocity="1.0"/>
    <dynamics damping="0.01" friction="0.0"/>
  </joint>
  <joint name="right_ankle_abduction" type="revolute">
    <parent link="right_shank"/>
    <child link="body_right_ankle"/>
    <axis xyz="1 0 0"/>
    <origin xyz="0 -0.391 0"/>
    <limit effort="29.0" lower="-0.418879020479" upper="0.401425727959" velocity="1.0"/>
    <dynamics damping="0.01" friction="0.0"/>
  </joint>
  <joint name="right_ankle_flexion" type="revolute">
    <parent link="body_right_ankle"/>
    <child link="right_foot"/>
    <axis xyz="0 0 1"/>
    <origin xyz="0 0 0"/>
    <limit effort="123.0" lower="-0.663225115758" upper="0.610865238198" velocity="1.0"/>
    <dynamics damping="0.01" friction="0.0"/>
  </joint>
  <!-- Left leg joints -->
  <joint name="left_hip_abduction" type="revolute">
    <parent link="pelvis"/>
    <child link="body_left_hip_1"/>
    <axis xyz="1 0 0"/>
    <origin xyz="0 0 -0.08925"/>
    <limit effort="108.0" lower="-0.541052068118" upper="0.925024503557" velocity="1.0"/>
    <dynamics damping="0.01" friction="0.0"/>
  </joint>
  <joint name="left_hip_rotation" type="revolute">
    <parent link="body_left_hip_1"/>
    <child link="body_left_hip_2"/>
    <axis xyz="0 1 0"/>
    <origin xyz="0 0 0"/>
    <limit effort="67.0" lower="-0.680678408278" upper="0.593411945678" velocity="1.0"/>
    <dynamics damping="0.01" friction="0.0"/>
  </joint>
  <joint name="left_hip_flexion" type="revolute">
    <parent link="body_left_hip_2"/>
    <child link="left_thigh"/>
    <axis xyz="0 0 1"/>
    <origin xyz="0 0 0"/>
    <limit effort="186.0" lower="-0.261799387799" upper="1.97222205475" velocity="1.0"/>
    <dynamics damping="0.01" friction="0.0"/>
  </joint>
  <joint name="left_knee_rotation" type="revolute">
    <parent link="left_thigh"/>
    <child link="body_left_knee"/>
    <axis xyz="0 1 0"/>
    <origin xyz="0 -0.442 0"/>
    <limit effort="22.0" lower="-0.610865238198" upper="0.750491578358" velocity="1.0"/>
    <dynamics damping="0.01" friction="0.0"/>
  </joint>
  <joint name="left_knee_flexion" type="revolute">
    <parent link="body_left_knee"/>
    <child link="left_shank"/>
    <axis xyz="0 0 1"/>
    <origin xyz="0 0 0"/>
    <limit effort="164.0" lower="-2.44346095279" upper="0.0872664625997" velocity="1.0"/>
    <dynamics damping="0.01" friction="0.0"/>
  </joint>
  <joint name="left_ankle_abduction" type="revolute">
    <parent link="left_shank"/>
    <child link="body_left_ankle"/>
    <axis xyz="1 0 0"/>
    <origin xyz="0 -0.391 0"/>
    <limit effort="29.0" lower="-0.401425727959" upper="0.418879020479" velocity="1.0"/>
    <dynamics damping="0.01" friction="0.0"/>
  </joint>
  <joint name="left_ankle_flexion" type="revolute">
    <parent link="body_left_ankle"/>
    <child link="left_foot"/>
    <axis xyz="0 0 1"/>
    <origin xyz="0 0 0"/>
    <limit effort="123.0" lower="-0.663225115758" upper="0.610865238198" velocity="1.0"/>
    <dynamics damping="0.01" friction="0.0"/>
  </joint>
  <!-- Gazebo plugin for ROS Control -->
  <!-- Note: if adding a Namespace here (other than "/"), the controller_manager should be in the same Namespace, as well as the spawner -->
  <gazebo>
    <!-- <plugin filename="libgazebo_ros_control.so" name="gazebo_ros_control">
      <robotNamespace>/dhm</robotNamespace>
    </plugin> -->
  </gazebo>
  <gazebo reference="root">
    <turnGravityOff> 0 </turnGravityOff>
  </gazebo>
  <gazebo reference="pelvis">
    <turnGravityOff> 0 </turnGravityOff>
    <material>Gazebo/Blue</material>
  </gazebo>
  <gazebo reference="body_L5_1">
    <turnGravityOff> 0 </turnGravityOff>
  </gazebo>
  <gazebo reference="body_L5_2">
    <turnGravityOff> 0 </turnGravityOff>
  </gazebo>
  <gazebo reference="lumbar_spine">
    <turnGravityOff> 0 </turnGravityOff>
    <material>Gazebo/Blue</material>
  </gazebo>
  <gazebo reference="body_T12_1">
    <turnGravityOff> 0 </turnGravityOff>
  </gazebo>
  <gazebo reference="body_T12_2">
    <turnGravityOff> 0 </turnGravityOff>
  </gazebo>
  <gazebo reference="thoracic_spine">
    <turnGravityOff> 0 </turnGravityOff>
    <material>Gazebo/Blue</material>
  </gazebo>
  <gazebo reference="body_C7_1">
    <turnGravityOff> 0 </turnGravityOff>
  </gazebo>
  <gazebo reference="body_C7_2">
    <turnGravityOff> 0 </turnGravityOff>
  </gazebo>
  <gazebo reference="neck">
    <turnGravityOff> 0 </turnGravityOff>
    <material>Gazebo/Blue</material>
  </gazebo>
  <gazebo reference="body_C1">
    <turnGravityOff> 0 </turnGravityOff>
  </gazebo>
  <gazebo reference="head">
    <turnGravityOff> 0 </turnGravityOff>
    <material>Gazebo/Blue</material>
  </gazebo>
  <gazebo reference="body_CSJ_right_clavicular">
    <turnGravityOff> 0 </turnGravityOff>
  </gazebo>
  <gazebo reference="right_clavicular">
    <turnGravityOff> 0 </turnGravityOff>
    <material>Gazebo/Blue</material>
  </gazebo>
  <gazebo reference="body_right_shoulder_1">
    <turnGravityOff> 0 </turnGravityOff>
  </gazebo>
  <gazebo reference="body_right_shoulder_2">
    <turnGravityOff> 0 </turnGravityOff>
  </gazebo>
  <gazebo reference="right_arm">
    <turnGravityOff> 0 </turnGravityOff>
    <material>Gazebo/Blue</material>
  </gazebo>
  <gazebo reference="body_right_elbow">
    <turnGravityOff> 0 </turnGravityOff>
  </gazebo>
  <gazebo reference="right_forearm">
    <turnGravityOff> 0 </turnGravityOff>
    <material>Gazebo/Blue</material>
  </gazebo>
  <gazebo reference="body_right_wrist">
    <turnGravityOff> 0 </turnGravityOff>
  </gazebo>
  <gazebo reference="right_hand">
    <turnGravityOff> 0 </turnGravityOff>
    <material>Gazebo/Blue</material>
  </gazebo>
  <gazebo reference="body_CSJ_left_clavicular">
    <turnGravityOff> 0 </turnGravityOff>
  </gazebo>
  <gazebo reference="left_clavicular">
    <turnGravityOff> 0 </turnGravityOff>
    <material>Gazebo/Blue</material>
  </gazebo>
  <gazebo reference="body_left_shoulder_1">
    <turnGravityOff> 0 </turnGravityOff>
  </gazebo>
  <gazebo reference="body_left_shoulder_2">
    <turnGravityOff> 0 </turnGravityOff>
  </gazebo>
  <gazebo reference="left_arm">
    <turnGravityOff> 0 </turnGravityOff>
    <material>Gazebo/Blue</material>
  </gazebo>
  <gazebo reference="body_left_elbow">
    <turnGravityOff> 0 </turnGravityOff>
  </gazebo>
  <gazebo reference="left_forearm">
    <turnGravityOff> 0 </turnGravityOff>
    <material>Gazebo/Blue</material>
  </gazebo>
  <gazebo reference="body_left_wrist">
    <turnGravityOff> 0 </turnGravityOff>
  </gazebo>
  <gazebo reference="left_hand">
    <turnGravityOff> 0 </turnGravityOff>
    <material>Gazebo/Blue</material>
  </gazebo>
  <gazebo reference="body_right_hip_1">
    <turnGravityOff> 0 </turnGravityOff>
  </gazebo>
  <gazebo reference="body_right_hip_2">
    <turnGravityOff> 0 </turnGravityOff>
  </gazebo>
  <gazebo reference="right_thigh">
    <turnGravityOff> 0 </turnGravityOff>
    <material>Gazebo/Blue</material>
  </gazebo>
  <gazebo reference="body_right_knee">
    <turnGravityOff> 0 </turnGravityOff>
  </gazebo>
  <gazebo reference="right_shank">
    <turnGravityOff> 0 </turnGravityOff>
    <material>Gazebo/Blue</material>
  </gazebo>
  <gazebo reference="body_right_ankle">
    <turnGravityOff> 0 </turnGravityOff>
  </gazebo>
  <gazebo reference="right_foot">
    <turnGravityOff> 0 </turnGravityOff>
    <mu1>0.7</mu1>
    <mu2>0.7</mu2>
    <material>Gazebo/Blue</material>
  </gazebo>
  <gazebo reference="body_left_hip_1">
    <turnGravityOff> 0 </turnGravityOff>
  </gazebo>
  <gazebo reference="body_left_hip_2">
    <turnGravityOff> 0 </turnGravityOff>
  </gazebo>
  <gazebo reference="left_thigh">
    <turnGravityOff> 0 </turnGravityOff>
    &gt;
		
    <material>Gazebo/Blue</material>
  </gazebo>
  <gazebo reference="body_left_knee">
    <turnGravityOff> 0 </turnGravityOff>
  </gazebo>
  <gazebo reference="left_shank">
    <turnGravityOff> 0 </turnGravityOff>
    <material>Gazebo/Blue</material>
  </gazebo>
  <gazebo reference="body_left_ankle">
    <turnGravityOff> 0 </turnGravityOff>
  </gazebo>
  <gazebo reference="left_foot">
    <turnGravityOff> 0 </turnGravityOff>
    <mu1>0.7</mu1>
    <mu2>0.7</mu2>
    <material>Gazebo/Blue</material>
  </gazebo>
  <transmission name="tran_lumbarspine_abduction">
    <type>transmission_interface/SimpleTransmission</type>
    <joint name="lumbarspine_abduction">
      <hardwareInterface>hardware_interface/EffortJointInterface</hardwareInterface>
    </joint>
    <actuator name="motor_lumbarspine_abduction">
      <hardwareInterface>hardware_interface/EffortJointInterface</hardwareInterface>
      <mechanicalReduction>1</mechanicalReduction>
    </actuator>
  </transmission>
  <transmission name="tran_lumbarspine_flexion">
    <type>transmission_interface/SimpleTransmission</type>
    <joint name="lumbarspine_flexion">
      <hardwareInterface>hardware_interface/EffortJointInterface</hardwareInterface>
    </joint>
    <actuator name="motor_lumbarspine_flexion">
      <hardwareInterface>hardware_interface/EffortJointInterface</hardwareInterface>
      <mechanicalReduction>1</mechanicalReduction>
    </actuator>
  </transmission>
  <transmission name="tran_lumbarspine_rotation">
    <type>transmission_interface/SimpleTransmission</type>
    <joint name="lumbarspine_rotation">
      <hardwareInterface>hardware_interface/EffortJointInterface</hardwareInterface>
    </joint>
    <actuator name="motor_lumbarspine_rotation">
      <hardwareInterface>hardware_interface/EffortJointInterface</hardwareInterface>
      <mechanicalReduction>1</mechanicalReduction>
    </actuator>
  </transmission>
  <transmission name="tran_thoracicspine_abduction">
    <type>transmission_interface/SimpleTransmission</type>
    <joint name="thoracicspine_abduction">
      <hardwareInterface>hardware_interface/EffortJointInterface</hardwareInterface>
    </joint>
    <actuator name="motor_thoracicspine_abduction">
      <hardwareInterface>hardware_interface/EffortJointInterface</hardwareInterface>
      <mechanicalReduction>1</mechanicalReduction>
    </actuator>
  </transmission>
  <transmission name="tran_thoracicspine_flexion">
    <type>transmission_interface/SimpleTransmission</type>
    <joint name="thoracicspine_flexion">
      <hardwareInterface>hardware_interface/EffortJointInterface</hardwareInterface>
    </joint>
    <actuator name="motor_thoracicspine_flexion">
      <hardwareInterface>hardware_interface/EffortJointInterface</hardwareInterface>
      <mechanicalReduction>1</mechanicalReduction>
    </actuator>
  </transmission>
  <transmission name="tran_thoracicspine_rotation">
    <type>transmission_interface/SimpleTransmission</type>
    <joint name="thoracicspine_rotation">
      <hardwareInterface>hardware_interface/EffortJointInterface</hardwareInterface>
    </joint>
    <actuator name="motor_thoracicspine_rotation">
      <hardwareInterface>hardware_interface/EffortJointInterface</hardwareInterface>
      <mechanicalReduction>1</mechanicalReduction>
    </actuator>
  </transmission>
  <transmission name="tran_neck_abduction">
    <type>transmission_interface/SimpleTransmission</type>
    <joint name="neck_abduction">
      <hardwareInterface>hardware_interface/EffortJointInterface</hardwareInterface>
    </joint>
    <actuator name="motor_neck_abduction">
      <hardwareInterface>hardware_interface/EffortJointInterface</hardwareInterface>
      <mechanicalReduction>1</mechanicalReduction>
    </actuator>
  </transmission>
  <transmission name="tran_neck_flexion">
    <type>transmission_interface/SimpleTransmission</type>
    <joint name="neck_flexion">
      <hardwareInterface>hardware_interface/EffortJointInterface</hardwareInterface>
    </joint>
    <actuator name="motor_neck_flexion">
      <hardwareInterface>hardware_interface/EffortJointInterface</hardwareInterface>
      <mechanicalReduction>1</mechanicalReduction>
    </actuator>
  </transmission>
  <transmission name="tran_neck_rotation">
    <type>transmission_interface/SimpleTransmission</type>
    <joint name="neck_rotation">
      <hardwareInterface>hardware_interface/EffortJointInterface</hardwareInterface>
    </joint>
    <actuator name="motor_neck_rotation">
      <hardwareInterface>hardware_interface/EffortJointInterface</hardwareInterface>
      <mechanicalReduction>1</mechanicalReduction>
    </actuator>
  </transmission>
  <transmission name="tran_head_abduction">
    <type>transmission_interface/SimpleTransmission</type>
    <joint name="head_abduction">
      <hardwareInterface>hardware_interface/EffortJointInterface</hardwareInterface>
    </joint>
    <actuator name="motor_head_abduction">
      <hardwareInterface>hardware_interface/EffortJointInterface</hardwareInterface>
      <mechanicalReduction>1</mechanicalReduction>
    </actuator>
  </transmission>
  <transmission name="tran_head_flexion">
    <type>transmission_interface/SimpleTransmission</type>
    <joint name="head_flexion">
      <hardwareInterface>hardware_interface/EffortJointInterface</hardwareInterface>
    </joint>
    <actuator name="motor_head_flexion">
      <hardwareInterface>hardware_interface/EffortJointInterface</hardwareInterface>
      <mechanicalReduction>1</mechanicalReduction>
    </actuator>
  </transmission>
  <transmission name="tran_right_clavicular_flexion">
    <type>transmission_interface/SimpleTransmission</type>
    <joint name="right_clavicular_flexion">
      <hardwareInterface>hardware_interface/EffortJointInterface</hardwareInterface>
    </joint>
    <actuator name="motor_right_clavicular_flexion">
      <hardwareInterface>hardware_interface/EffortJointInterface</hardwareInterface>
      <mechanicalReduction>1</mechanicalReduction>
    </actuator>
  </transmission>
  <transmission name="tran_right_clavicular_abduction">
    <type>transmission_interface/SimpleTransmission</type>
    <joint name="right_clavicular_abduction">
      <hardwareInterface>hardware_interface/EffortJointInterface</hardwareInterface>
    </joint>
    <actuator name="motor_right_clavicular_abduction">
      <hardwareInterface>hardware_interface/EffortJointInterface</hardwareInterface>
      <mechanicalReduction>1</mechanicalReduction>
    </actuator>
  </transmission>
  <transmission name="tran_right_shoulder_abduction">
    <type>transmission_interface/SimpleTransmission</type>
    <joint name="right_shoulder_abduction">
      <hardwareInterface>hardware_interface/EffortJointInterface</hardwareInterface>
    </joint>
    <actuator name="motor_right_shoulder_abduction">
      <hardwareInterface>hardware_interface/EffortJointInterface</hardwareInterface>
      <mechanicalReduction>1</mechanicalReduction>
    </actuator>
  </transmission>
  <transmission name="tran_right_shoulder_rotation">
    <type>transmission_interface/SimpleTransmission</type>
    <joint name="right_shoulder_rotation">
      <hardwareInterface>hardware_interface/EffortJointInterface</hardwareInterface>
    </joint>
    <actuator name="motor_right_shoulder_rotation">
      <hardwareInterface>hardware_interface/EffortJointInterface</hardwareInterface>
      <mechanicalReduction>1</mechanicalReduction>
    </actuator>
  </transmission>
  <transmission name="tran_right_shoulder_flexion">
    <type>transmission_interface/SimpleTransmission</type>
    <joint name="right_shoulder_flexion">
      <hardwareInterface>hardware_interface/EffortJointInterface</hardwareInterface>
    </joint>
    <actuator name="motor_right_shoulder_flexion">
      <hardwareInterface>hardware_interface/EffortJointInterface</hardwareInterface>
      <mechanicalReduction>1</mechanicalReduction>
    </actuator>
  </transmission>
  <transmission name="tran_right_elbow_flexion">
    <type>transmission_interface/SimpleTransmission</type>
    <joint name="right_elbow_flexion">
      <hardwareInterface>hardware_interface/EffortJointInterface</hardwareInterface>
    </joint>
    <actuator name="motor_right_elbow_flexion">
      <hardwareInterface>hardware_interface/EffortJointInterface</hardwareInterface>
      <mechanicalReduction>1</mechanicalReduction>
    </actuator>
  </transmission>
  <transmission name="tran_right_elbow_rotation">
    <type>transmission_interface/SimpleTransmission</type>
    <joint name="right_elbow_rotation">
      <hardwareInterface>hardware_interface/EffortJointInterface</hardwareInterface>
    </joint>
    <actuator name="motor_right_elbow_rotation">
      <hardwareInterface>hardware_interface/EffortJointInterface</hardwareInterface>
      <mechanicalReduction>1</mechanicalReduction>
    </actuator>
  </transmission>
  <transmission name="tran_right_wrist_flexion">
    <type>transmission_interface/SimpleTransmission</type>
    <joint name="right_wrist_flexion">
      <hardwareInterface>hardware_interface/EffortJointInterface</hardwareInterface>
    </joint>
    <actuator name="motor_right_wrist_flexion">
      <hardwareInterface>hardware_interface/EffortJointInterface</hardwareInterface>
      <mechanicalReduction>1</mechanicalReduction>
    </actuator>
  </transmission>
  <transmission name="tran_right_wrist_abduction">
    <type>transmission_interface/SimpleTransmission</type>
    <joint name="right_wrist_abduction">
      <hardwareInterface>hardware_interface/EffortJointInterface</hardwareInterface>
    </joint>
    <actuator name="motor_right_wrist_abduction">
      <hardwareInterface>hardware_interface/EffortJointInterface</hardwareInterface>
      <mechanicalReduction>1</mechanicalReduction>
    </actuator>
  </transmission>
  <transmission name="tran_left_clavicular_flexion">
    <type>transmission_interface/SimpleTransmission</type>
    <joint name="left_clavicular_flexion">
      <hardwareInterface>hardware_interface/EffortJointInterface</hardwareInterface>
    </joint>
    <actuator name="motor_left_clavicular_flexion">
      <hardwareInterface>hardware_interface/EffortJointInterface</hardwareInterface>
      <mechanicalReduction>1</mechanicalReduction>
    </actuator>
  </transmission>
  <transmission name="tran_left_clavicular_abduction">
    <type>transmission_interface/SimpleTransmission</type>
    <joint name="left_clavicular_abduction">
      <hardwareInterface>hardware_interface/EffortJointInterface</hardwareInterface>
    </joint>
    <actuator name="motor_left_clavicular_abduction">
      <hardwareInterface>hardware_interface/EffortJointInterface</hardwareInterface>
      <mechanicalReduction>1</mechanicalReduction>
    </actuator>
  </transmission>
  <transmission name="tran_left_shoulder_abduction">
    <type>transmission_interface/SimpleTransmission</type>
    <joint name="left_shoulder_abduction">
      <hardwareInterface>hardware_interface/EffortJointInterface</hardwareInterface>
    </joint>
    <actuator name="motor_left_shoulder_abduction">
      <hardwareInterface>hardware_interface/EffortJointInterface</hardwareInterface>
      <mechanicalReduction>1</mechanicalReduction>
    </actuator>
  </transmission>
  <transmission name="tran_left_shoulder_rotation">
    <type>transmission_interface/SimpleTransmission</type>
    <joint name="left_shoulder_rotation">
      <hardwareInterface>hardware_interface/EffortJointInterface</hardwareInterface>
    </joint>
    <actuator name="motor_left_shoulder_rotation">
      <hardwareInterface>hardware_interface/EffortJointInterface</hardwareInterface>
      <mechanicalReduction>1</mechanicalReduction>
    </actuator>
  </transmission>
  <transmission name="tran_left_shoulder_flexion">
    <type>transmission_interface/SimpleTransmission</type>
    <joint name="left_shoulder_flexion">
      <hardwareInterface>hardware_interface/EffortJointInterface</hardwareInterface>
    </joint>
    <actuator name="motor_left_shoulder_flexion">
      <hardwareInterface>hardware_interface/EffortJointInterface</hardwareInterface>
      <mechanicalReduction>1</mechanicalReduction>
    </actuator>
  </transmission>
  <transmission name="tran_left_elbow_flexion">
    <type>transmission_interface/SimpleTransmission</type>
    <joint name="left_elbow_flexion">
      <hardwareInterface>hardware_interface/EffortJointInterface</hardwareInterface>
    </joint>
    <actuator name="motor_left_elbow_flexion">
      <hardwareInterface>hardware_interface/EffortJointInterface</hardwareInterface>
      <mechanicalReduction>1</mechanicalReduction>
    </actuator>
  </transmission>
  <transmission name="tran_left_elbow_rotation">
    <type>transmission_interface/SimpleTransmission</type>
    <joint name="left_elbow_rotation">
      <hardwareInterface>hardware_interface/EffortJointInterface</hardwareInterface>
    </joint>
    <actuator name="motor_left_elbow_rotation">
      <hardwareInterface>hardware_interface/EffortJointInterface</hardwareInterface>
      <mechanicalReduction>1</mechanicalReduction>
    </actuator>
  </transmission>
  <transmission name="tran_left_wrist_flexion">
    <type>transmission_interface/SimpleTransmission</type>
    <joint name="left_wrist_flexion">
      <hardwareInterface>hardware_interface/EffortJointInterface</hardwareInterface>
    </joint>
    <actuator name="motor_left_wrist_flexion">
      <hardwareInterface>hardware_interface/EffortJointInterface</hardwareInterface>
      <mechanicalReduction>1</mechanicalReduction>
    </actuator>
  </transmission>
  <transmission name="tran_left_wrist_abduction">
    <type>transmission_interface/SimpleTransmission</type>
    <joint name="left_wrist_abduction">
      <hardwareInterface>hardware_interface/EffortJointInterface</hardwareInterface>
    </joint>
    <actuator name="motor_left_wrist_abduction">
      <hardwareInterface>hardware_interface/EffortJointInterface</hardwareInterface>
      <mechanicalReduction>1</mechanicalReduction>
    </actuator>
  </transmission>
  <transmission name="tran_right_hip_abduction">
    <type>transmission_interface/SimpleTransmission</type>
    <joint name="right_hip_abduction">
      <hardwareInterface>hardware_interface/EffortJointInterface</hardwareInterface>
    </joint>
    <actuator name="motor_right_hip_abduction">
      <hardwareInterface>hardware_interface/EffortJointInterface</hardwareInterface>
      <mechanicalReduction>1</mechanicalReduction>
    </actuator>
  </transmission>
  <transmission name="tran_right_hip_rotation">
    <type>transmission_interface/SimpleTransmission</type>
    <joint name="right_hip_rotation">
      <hardwareInterface>hardware_interface/EffortJointInterface</hardwareInterface>
    </joint>
    <actuator name="motor_right_hip_rotation">
      <hardwareInterface>hardware_interface/EffortJointInterface</hardwareInterface>
      <mechanicalReduction>1</mechanicalReduction>
    </actuator>
  </transmission>
  <transmission name="tran_right_hip_flexion">
    <type>transmission_interface/SimpleTransmission</type>
    <joint name="right_hip_flexion">
      <hardwareInterface>hardware_interface/EffortJointInterface</hardwareInterface>
    </joint>
    <actuator name="motor_right_hip_flexion">
      <hardwareInterface>hardware_interface/EffortJointInterface</hardwareInterface>
      <mechanicalReduction>1</mechanicalReduction>
    </actuator>
  </transmission>
  <transmission name="tran_right_knee_rotation">
    <type>transmission_interface/SimpleTransmission</type>
    <joint name="right_knee_rotation">
      <hardwareInterface>hardware_interface/EffortJointInterface</hardwareInterface>
    </joint>
    <actuator name="motor_right_knee_rotation">
      <hardwareInterface>hardware_interface/EffortJointInterface</hardwareInterface>
      <mechanicalReduction>1</mechanicalReduction>
    </actuator>
  </transmission>
  <transmission name="tran_right_knee_flexion">
    <type>transmission_interface/SimpleTransmission</type>
    <joint name="right_knee_flexion">
      <hardwareInterface>hardware_interface/EffortJointInterface</hardwareInterface>
    </joint>
    <actuator name="motor_right_knee_flexion">
      <hardwareInterface>hardware_interface/EffortJointInterface</hardwareInterface>
      <mechanicalReduction>1</mechanicalReduction>
    </actuator>
  </transmission>
  <transmission name="tran_right_ankle_flexion">
    <type>transmission_interface/SimpleTransmission</type>
    <joint name="right_ankle_flexion">
      <hardwareInterface>hardware_interface/EffortJointInterface</hardwareInterface>
    </joint>
    <actuator name="motor_right_ankle_flexion">
      <hardwareInterface>hardware_interface/EffortJointInterface</hardwareInterface>
      <mechanicalReduction>1</mechanicalReduction>
    </actuator>
  </transmission>
  <transmission name="tran_right_ankle_abduction">
    <type>transmission_interface/SimpleTransmission</type>
    <joint name="right_ankle_abduction">
      <hardwareInterface>hardware_interface/EffortJointInterface</hardwareInterface>
    </joint>
    <actuator name="motor_right_ankle_abduction">
      <hardwareInterface>hardware_interface/EffortJointInterface</hardwareInterface>
      <mechanicalReduction>1</mechanicalReduction>
    </actuator>
  </transmission>
  <transmission name="tran_left_hip_abduction">
    <type>transmission_interface/SimpleTransmission</type>
    <joint name="left_hip_abduction">
      <hardwareInterface>hardware_interface/EffortJointInterface</hardwareInterface>
    </joint>
    <actuator name="motor_left_hip_abduction">
      <hardwareInterface>hardware_interface/EffortJointInterface</hardwareInterface>
      <mechanicalReduction>1</mechanicalReduction>
    </actuator>
  </transmission>
  <transmission name="tran_left_hip_rotation">
    <type>transmission_interface/SimpleTransmission</type>
    <joint name="left_hip_rotation">
      <hardwareInterface>hardware_interface/EffortJointInterface</hardwareInterface>
    </joint>
    <actuator name="motor_left_hip_rotation">
      <hardwareInterface>hardware_interface/EffortJointInterface</hardwareInterface>
      <mechanicalReduction>1</mechanicalReduction>
    </actuator>
  </transmission>
  <transmission name="tran_left_hip_flexion">
    <type>transmission_interface/SimpleTransmission</type>
    <joint name="left_hip_flexion">
      <hardwareInterface>hardware_interface/EffortJointInterface</hardwareInterface>
    </joint>
    <actuator name="motor_left_hip_flexion">
      <hardwareInterface>hardware_interface/EffortJointInterface</hardwareInterface>
      <mechanicalReduction>1</mechanicalReduction>
    </actuator>
  </transmission>
  <transmission name="tran_left_knee_rotation">
    <type>transmission_interface/SimpleTransmission</type>
    <joint name="left_knee_rotation">
      <hardwareInterface>hardware_interface/EffortJointInterface</hardwareInterface>
    </joint>
    <actuator name="motor_left_knee_rotation">
      <hardwareInterface>hardware_interface/EffortJointInterface</hardwareInterface>
      <mechanicalReduction>1</mechanicalReduction>
    </actuator>
  </transmission>
  <transmission name="tran_left_knee_flexion">
    <type>transmission_interface/SimpleTransmission</type>
    <joint name="left_knee_flexion">
      <hardwareInterface>hardware_interface/EffortJointInterface</hardwareInterface>
    </joint>
    <actuator name="motor_left_knee_flexion">
      <hardwareInterface>hardware_interface/EffortJointInterface</hardwareInterface>
      <mechanicalReduction>1</mechanicalReduction>
    </actuator>
  </transmission>
  <transmission name="tran_left_ankle_flexion">
    <type>transmission_interface/SimpleTransmission</type>
    <joint name="left_ankle_flexion">
      <hardwareInterface>hardware_interface/EffortJointInterface</hardwareInterface>
    </joint>
    <actuator name="motor_left_ankle_flexion">
      <hardwareInterface>hardware_interface/EffortJointInterface</hardwareInterface>
      <mechanicalReduction>1</mechanicalReduction>
    </actuator>
  </transmission>
  <transmission name="tran_left_ankle_abduction">
    <type>transmission_interface/SimpleTransmission</type>
    <joint name="left_ankle_abduction">
      <hardwareInterface>hardware_interface/EffortJointInterface</hardwareInterface>
    </joint>
    <actuator name="motor_left_ankle_abduction">
      <hardwareInterface>hardware_interface/EffortJointInterface</hardwareInterface>
      <mechanicalReduction>1</mechanicalReduction>
    </actuator>
  </transmission>
</robot>
